Workbook
Name dd: FoodLibrary[Food Name]
Name dd: FoodLibrary[Food Name]
Name FoodList: FoodLibrary[Food Name]
Name FoodList: FoodLibrary[Food Name]
Name FoodNameList: FoodLibrary[Food Name]
Name FoodNameList: FoodLibrary[Food Name]

Sheet Macro Goals
A1: 💪 Muscle Building & Diet Tracker
A2: Professional macro target setup for cut, maintenance, and bulk. Edit yellow cells only.
A4: 📅 Tracking & Goal Setup
A5: Start Date | B5: 46311 | D5: 🎯 Goal | E5: Daily Calories | F5: Protein (g) | G5: Fat (g) | H5: Carbs (g)
A6: End Date | B6: =B5+B7-1 -> 46370 | D6: Cut | E6: =$B$17 -> 2334 | F6: =ROUND(IF($E$35<>"",$E$35*$B$41,$B$9*2),0) -> 123 | G6: =MAX($E$45,ROUND(E6*$B$42/9,0)) -> 65 | H6: =MAX(0,ROUND((E6-(F6*4+G6*9))/4,0)) -> 314
A7: Duration (days) | B7: 60 | D7: Maintenance | E7: =$B$16 -> 2431 | F7: =ROUND(IF($E$35<>"",$E$35*2,$B$9*1.8),0) -> 112 | G7: =MAX($E$45,ROUND(E7*$B$42/9,0)) -> 68 | H7: =MAX(0,ROUND((E7-(F7*4+G7*9))/4,0)) -> 343
A8: Goal | B8: Maintenance | D8: Bulk | E8: =$B$18 -> 2553 | F8: =ROUND(IF($E$35<>"",$E$35*2.2,$B$9*2),0) -> 123 | G8: =MAX($E$45,ROUND(E8*$B$42/9,0)) -> 71 | H8: =MAX(0,ROUND((E8-(F8*4+G8*9))/4,0)) -> 356
A9: Weight (kg) | B9: 66 | D9: Selected Goal | E9: =IF($B$8="Cut",E6,IF($B$8="Maintenance",E7,E8)) -> 2431 | F9: =IF($B$8="Cut",F6,IF($B$8="Maintenance",F7,F8)) -> 112 | G9: =IF($B$8="Cut",G6,IF($B$8="Maintenance",G7,G8)) -> 68 | H9: =IF($B$8="Cut",H6,IF($B$8="Maintenance",H7,H8)) -> 343
A10: Height (cm) | B10: 174
A11: Age | B11: 45
A12: Activity Multiplier | B12: =$E$41 -> 1.6 | D12: 📊 Daily Summary | E12: Calories | F12: Carbs (g) | G12: Protein (g) | H12: Fat (g)
A13: Burn % / Cut deficit | B13: 0.04 | D13: Consumed | E13: ='Daily Intake'!E6 -> 2447.2084 | F13: ='Daily Intake'!F6 -> 306.82939 | G13: ='Daily Intake'!G6 -> 186.88942 | H13: ='Daily Intake'!H6 -> 39.914684
A14: Bulk % / Surplus | B14: 0.05 | D14: Target | E14: =$E$9 -> 2431 | F14: =$H$9 -> 343 | G14: =$F$9 -> 112 | H14: =$G$9 -> 68
A15: BMR | B15: =$E$38 -> 1582 | D15: Remaining | E15: =E14-E13 -> -16.208421 | F15: =F14-F13 -> 36.170614 | G15: =G14-G13 -> -74.889421 | H15: =H14-H13 -> 28.085316
A16: TDEE / Maintenance | B16: =$E$42 -> 2431 | D16: % of Target | E16: =IFERROR(E13/E14,0) -> 1.0066674 | F16: =IFERROR(F13/F14,0) -> 0.89454631 | G16: =IFERROR(G13/G14,0) -> 1.6686555 | H16: =IFERROR(H13/H14,0) -> 0.58698065
A17: Cut Calories | B17: =$E$43 -> 2334
A18: Bulk Calories | B18: =$E$44 -> 2553
A19: Activity multiplier note | B19: Exercise inputs calculate TDEE, then Adjust TDEE Value in B28 is subtracted from maintenance. Cut and Bulk are based on the adjusted maintenance value.
A21: 🏃 Exercise-Based Activity Multiplier
A22: B12 now calculates from exercise count, intensity, duration, and weekly frequency. Edit yellow cells only.
A24: Type of exercise | B24: Resistance | D24: Standard MET by exercise | E24: {=_xlfn.SWITCH($B$24,"Resistance",6,"Running",9.8,"Walking",3.5,"Swimming",8,"Badminton",5.5,"Other",5,5)} -> 6
A25: Intensity | B25: High | D25: Intensity-adjusted MET | E25: {=ROUND($E$24*_xlfn.SWITCH($B$25,"Low",0.8,"Moderate",1,"High",1.25,"Very high",1.5,1),1)} -> 7.5
A26: Duration per session (min) | B26: 110 | D26: Net exercise kcal / session | E26: =ROUND(MAX(0,$E$25-1)*3.5*$B$9/200*$B$26,0) -> 826
A27: Sessions per week | B27: 4 | D27: Weekly net exercise kcal | E27: =$E$26*$B$27 -> 3304
A28: Adjust TDEE Value (kcal) | B28: 100 | D28: Daily net exercise kcal | E28: =ROUND($E$27/7,0) -> 472
D29: Exercise-only multiplier | E29: =ROUND(1+($E$28/$E$38),2) -> 1.3
A31: ⚖️ Realistic BMR, PAL & Macro Model
A32: Uses Mifflin-St Jeor for baseline BMR, optional Katch-McArdle when body fat is entered, and a standard lifestyle PAL plus logged exercise.
A34: Sex | B34: Male | D34: BMI | E34: =ROUND($B$9/(($B$10/100)^2),1) -> 21.8
A35: Body fat % | B35: 0.15 | D35: Lean body mass kg | E35: =IF($B$35>0,ROUND($B$9*(1-$B$35),1),"") -> 56.1
A36: BMR method | B36: Auto | D36: Mifflin-St Jeor BMR | E36: =ROUND((10*$B$9)+(6.25*$B$10)-(5*$B$11)+IF($B$34="Male",5,-161),0) -> 1528
A37: Non-exercise activity | B37: Light daily movement | D37: Katch-McArdle BMR | E37: =IF($B$35>0,ROUND(370+(21.6*$E$35),0),"") -> 1582
A38: Cut deficit from Burn % | B38: =$B$13 -> 0.04 | D38: Selected BMR | E38: =IF($B$36="Mifflin",$E$36,IF($B$36="Katch",$E$37,IF($B$35>0,$E$37,$E$36))) -> 1582
A39: Bulk surplus from Bulk % | B39: =$B$14 -> 0.05 | D39: Non-exercise factor | E39: {=_xlfn.SWITCH($B$37,"Sedentary desk",1.2,"Light daily movement",1.3,"Active job",1.45,"Very active job",1.6,1.2)} -> 1.3
A40: Logged exercise mode | B40: Include logged exercise | D40: Net exercise add-on | E40: =ROUND($E$28/$E$38,2) -> 0.3
A41: Protein g per kg lean mass | B41: 2.2 | D41: Final activity multiplier | E41: =IF($B$40="Include logged exercise",MIN(2.2,ROUND($E$39+$E$40,2)),$E$39) -> 1.6
A42: Fat % of calories | B42: 0.25 | D42: Maintenance calories | E42: =MAX(0,ROUND($E$38*$E$41-N($B$28),0)) -> 2431
A43: Minimum fat g / kg weight | B43: 0.6 | D43: Cut calories | E43: =ROUND($E$42*(1-$B$13),0) -> 2334
D44: Bulk calories | E44: =ROUND($E$42*(1+$B$14),0) -> 2553
D45: Fat grams floor | E45: =ROUND($B$9*$B$43,0) -> 40
...

Sheet Daily Intake
A1: 💪 Daily Food Intake
A2: Build your day with up to 10 foods per meal. Yellow cells are for goal, food, grams, and notes.
A4: 📅 Start Date | B4: ='Macro Goals'!B5 -> 46311
A5: End Date | B5: ='Macro Goals'!B6 -> 46370 | D5: 📊 Today Summary | E5: Calories | F5: Carbs (g) | G5: Protein (g) | H5: Fat (g)
A6: Duration (days) | B6: 60 | D6: Consumed | E6: =SUM(D18:D57) -> 2447.2084 | F6: =SUM(E18:E57) -> 306.82939 | G6: =SUM(F18:F57) -> 186.88942 | H6: =SUM(G18:G57) -> 39.914684
A7: Goal | B7: Maintenance | D7: Target | E7: =B8 -> 2431 | F7: =B11 -> 343 | G7: =B9 -> 112 | H7: =B10 -> 68
A8: Calorie Target | B8: ='Macro Goals'!E9 -> 2431 | D8: Remaining | E8: =E7-E6 -> -16.208421 | F8: =F7-F6 -> 36.170614 | G8: =G7-G6 -> -74.889421 | H8: =H7-H6 -> 28.085316 | P8: S
A9: Protein Target | B9: ='Macro Goals'!F9 -> 112 | D9: % of Target | E9: =IFERROR(E6/E7,0) -> 1.0066674 | F9: =IFERROR(F6/F7,0) -> 0.89454631 | G9: =IFERROR(G6/G7,0) -> 1.6686555 | H9: =IFERROR(H6/H7,0) -> 0.58698065
A10: Fat Target | B10: ='Macro Goals'!G9 -> 68
A11: Carb Target | B11: ='Macro Goals'!H9 -> 343 | D11: 🍽 Meal Summary | E11: Calories | F11: Carbs (g) | G11: Protein (g) | H11: Fat (g)
D12: Meal 1 | E12: =SUMIFS(D18:D57,A18:A57,D12) -> 695.01921 | F12: =SUMIFS(E18:E57,A18:A57,D12) -> 84.287193 | G12: =SUMIFS(F18:F57,A18:A57,D12) -> 52.196711 | H12: =SUMIFS(G18:G57,A18:A57,D12) -> 11.134342
D13: Meal 2 | E13: =SUMIFS(D18:D57,A18:A57,D13) -> 667.02 | F13: =SUMIFS(E18:E57,A18:A57,D13) -> 74.14 | G13: =SUMIFS(F18:F57,A18:A57,D13) -> 54.36 | H13: =SUMIFS(G18:G57,A18:A57,D13) -> 15.61
D14: Meal 3 | E14: =SUMIFS(D18:D57,A18:A57,D14) -> 430.15 | F14: =SUMIFS(E18:E57,A18:A57,D14) -> 68.715 | G14: =SUMIFS(F18:F57,A18:A57,D14) -> 29.536 | H14: =SUMIFS(G18:G57,A18:A57,D14) -> 3.636
D15: Meal 4 | E15: =SUMIFS(D18:D57,A18:A57,D15) -> 655.01921 | F15: =SUMIFS(E18:E57,A18:A57,D15) -> 79.687193 | G15: =SUMIFS(F18:F57,A18:A57,D15) -> 50.796711 | H15: =SUMIFS(G18:G57,A18:A57,D15) -> 9.5343421
A17: Meal | B17: Food Name | C17: Grams | D17: Calories | E17: Carbs (g) | F17: Protein (g) | G17: Fat (g) | H17: Notes | I17: Source
A18: Meal 1 | B18: Harraways Oat | C18: 120 | D18: {=_xlfn.LET(_xlpm.food,TRIM(DailyIntake[[#This Row],[Food Name]]),_xlpm.g,DailyIntake[[#This Row],[Grams]],_xlpm.names,FoodLibrary[Lookup Key],_xlpm.custom,_xlfn.XLOOKUP(_xlpm.food,_xlpm.names,FoodLibrary[Custom],""),_xlpm.base,IFERROR(IF(VALUE(_xlpm.custom)>0,VALUE(_xlpm.custom),100),100),_xlpm.nutrient,_xlfn.XLOOKUP(_xlpm.food,_xlpm.names,FoodLibrary[Calories / 100g],0),IF(OR(_xlpm.food="",_xlpm.g=""),0,IFERROR(_xlpm.g*_xlpm.nutrient/_xlpm.base,0)))} -> 433.2 | E18: {=_xlfn.LET(_xlpm.food,TRIM(DailyIntake[[#This Row],[Food Name]]),_xlpm.g,DailyIntake[[#This Row],[Grams]],_xlpm.names,FoodLibrary[Lookup Key],_xlpm.custom,_xlfn.XLOOKUP(_xlpm.food,_xlpm.names,FoodLibrary[Custom],""),_xlpm.base,IFERROR(IF(VALUE(_xlpm.custom)>0,VALUE(_xlpm.custom),100),100),_xlpm.nutrient,_xlfn.XLOOKUP(_xlpm.food,_xlpm.names,FoodLibrary[Carbs / 100g],0),IF(OR(_xlpm.food="",_xlpm.g=""),0,IFERROR(_xlpm.g*_xlpm.nutrient/_xlpm.base,0)))} -> 65.16 | F18: {=_xlfn.LET(_xlpm.food,TRIM(DailyIntake[[#This Row],[Food Name]]),_xlpm.g,DailyIntake[[#This Row],[Grams]],_xlpm.names,FoodLibrary[Lookup Key],_xlpm.custom,_xlfn.XLOOKUP(_xlpm.food,_xlpm.names,FoodLibrary[Custom],""),_xlpm.base,IFERROR(IF(VALUE(_xlpm.custom)>0,VALUE(_xlpm.custom),100),100),_xlpm.nutrient,_xlfn.XLOOKUP(_xlpm.food,_xlpm.names,FoodLibrary[Protein / 100g],0),IF(OR(_xlpm.food="",_xlpm.g=""),0,IFERROR(_xlpm.g*_xlpm.nutrient/_xlpm.base,0)))} -> 16.8 | G18: {=_xlfn.LET(_xlpm.food,TRIM(DailyIntake[[#This Row],[Food Name]]),_xlpm.g,DailyIntake[[#This Row],[Grams]],_xlpm.names,FoodLibrary[Lookup Key],_xlpm.custom,_xlfn.XLOOKUP(_xlpm.food,_xlpm.names,FoodLibrary[Custom],""),_xlpm.base,IFERROR(IF(VALUE(_xlpm.custom)>0,VALUE(_xlpm.custom),100),100),_xlpm.nutrient,_xlfn.XLOOKUP(_xlpm.food,_xlpm.names,FoodLibrary[Fat / 100g],0),IF(OR(_xlpm.food="",_xlpm.g=""),0,IFERROR(_xlpm.g*_xlpm.nutrient/_xlpm.base,0)))} -> 8.16 | I18: {=_xlfn.LET(_xlpm.food,TRIM(DailyIntake[[#This Row],[Food Name]]),_xlpm.names,FoodLibrary[Lookup Key],_xlpm.custom,_xlfn.XLOOKUP(_xlpm.food,_xlpm.names,FoodLibrary[Custom],""),_xlpm.base,IFERROR(VALUE(_xlpm.custom),0),IF(_xlpm.food="","",IF(_xlpm.base>0,"Food Library custom","Food Library /100g")))} -> Food Library /100g
A19: Meal 1 | B19: Chobani Greek | C19: 100 | D19: {=_xlfn.LET(_xlpm.food,TRIM(DailyIntake[[#This Row],[Food Name]]),_xlpm.g,DailyIntake[[#This Row],[Grams]],_xlpm.names,FoodLibrary[Lookup Key],_xlpm.custom,_xlfn.XLOOKUP(_xlpm.food,_xlpm.names,FoodLibrary[Custom],""),_xlpm.base,IFERROR(IF(VALUE(_xlpm.custom)>0,VALUE(_xlpm.custom),100),100),_xlpm.nutrient,_xlfn.XLOOKUP(_xlpm.food,_xlpm.names,FoodLibrary[Calories / 100g],0),IF(OR(_xlpm.food="",_xlpm.g=""),0,IFERROR(_xlpm.g*_xlpm.nutrient/_xlpm.base,0)))} -> 55.625 | E19: {=_xlfn.LET(_xlpm.food,TRIM(DailyIntake[[#This Row],[Food Name]]),_xlpm.g,DailyIntake[[#This Row],[Grams]],_xlpm.names,FoodLibrary[Lookup Key],_xlpm.custom,_xlfn.XLOOKUP(_xlpm.food,_xlpm.names,FoodLibrary[Custom],""),_xlpm.base,IFERROR(IF(VALUE(_xlpm.custom)>0,VALUE(_xlpm.custom),100),100),_xlpm.nutrient,_xlfn.XLOOKUP(_xlpm.food,_xlpm.names,FoodLibrary[Carbs / 100g],0),IF(OR(_xlpm.food="",_xlpm.g=""),0,IFERROR(_xlpm.g*_xlpm.nutrient/_xlpm.base,0)))} -> 4 | F19: {=_xlfn.LET(_xlpm.food,TRIM(DailyIntake[[#This Row],[Food Name]]),_xlpm.g,DailyIntake[[#This Row],[Grams]],_xlpm.names,FoodLibrary[Lookup Key],_xlpm.custom,_xlfn.XLOOKUP(_xlpm.food,_xlpm.names,FoodLibrary[Custom],""),_xlpm.base,IFERROR(IF(VALUE(_xlpm.custom)>0,VALUE(_xlpm.custom),100),100),_xlpm.nutrient,_xlfn.XLOOKUP(_xlpm.food,_xlpm.names,FoodLibrary[Protein / 100g],0),IF(OR(_xlpm.food="",_xlpm.g=""),0,IFERROR(_xlpm.g*_xlpm.nutrient/_xlpm.base,0)))} -> 9.3125 | G19: {=_xlfn.LET(_xlpm.food,TRIM(DailyIntake[[#This Row],[Food Name]]),_xlpm.g,DailyIntake[[#This Row],[Grams]],_xlpm.names,FoodLibrary[Lookup Key],_xlpm.custom,_xlfn.XLOOKUP(_xlpm.food,_xlpm.names,FoodLibrary[Custom],""),_xlpm.base,IFERROR(IF(VALUE(_xlpm.custom)>0,VALUE(_xlpm.custom),100),100),_xlpm.nutrient,_xlfn.XLOOKUP(_xlpm.food,_xlpm.names,FoodLibrary[Fat / 100g],0),IF(OR(_xlpm.food="",_xlpm.g=""),0,IFERROR(_xlpm.g*_xlpm.nutrient/_xlpm.base,0)))} -> 0.1875 | I19: {=_xlfn.LET(_xlpm.food,TRIM(DailyIntake[[#This Row],[Food Name]]),_xlpm.names,FoodLibrary[Lookup Key],_xlpm.custom,_xlfn.XLOOKUP(_xlpm.food,_xlpm.names,FoodLibrary[Custom],""),_xlpm.base,IFERROR(VALUE(_xlpm.custom),0),IF(_xlpm.food="","",IF(_xlpm.base>0,"Food Library custom","Food Library /100g")))} -> Food Library /100g
A20: Meal 1 | B20: Mixed Berries | C20: 100 | D20: {=_xlfn.LET(_xlpm.food,TRIM(DailyIntake[[#This Row],[Food Name]]),_xlpm.g,DailyIntake[[#This Row],[Grams]],_xlpm.names,FoodLibrary[Lookup Key],_xlpm.custom,_xlfn.XLOOKUP(_xlpm.food,_xlpm.names,FoodLibrary[Custom],""),_xlpm.base,IFERROR(IF(VALUE(_xlpm.custom)>0,VALUE(_xlpm.custom),100),100),_xlpm.nutrient,_xlfn.XLOOKUP(_xlpm.food,_xlpm.names,FoodLibrary[Calories / 100g],0),IF(OR(_xlpm.food="",_xlpm.g=""),0,IFERROR(_xlpm.g*_xlpm.nutrient/_xlpm.base,0)))} -> 43.26 | E20: {=_xlfn.LET(_xlpm.food,TRIM(DailyIntake[[#This Row],[Food Name]]),_xlpm.g,DailyIntake[[#This Row],[Grams]],_xlpm.names,FoodLibrary[Lookup Key],_xlpm.custom,_xlfn.XLOOKUP(_xlpm.food,_xlpm.names,FoodLibrary[Custom],""),_xlpm.base,IFERROR(IF(VALUE(_xlpm.custom)>0,VALUE(_xlpm.custom),100),100),_xlpm.nutrient,_xlfn.XLOOKUP(_xlpm.food,_xlpm.names,FoodLibrary[Carbs / 100g],0),IF(OR(_xlpm.food="",_xlpm.g=""),0,IFERROR(_xlpm.g*_xlpm.nutrient/_xlpm.base,0)))} -> 6.4 | F20: {=_xlfn.LET(_xlpm.food,TRIM(DailyIntake[[#This Row],[Food Name]]),_xlpm.g,DailyIntake[[#This Row],[Grams]],_xlpm.names,FoodLibrary[Lookup Key],_xlpm.custom,_xlfn.XLOOKUP(_xlpm.food,_xlpm.names,FoodLibrary[Custom],""),_xlpm.base,IFERROR(IF(VALUE(_xlpm.custom)>0,VALUE(_xlpm.custom),100),100),_xlpm.nutrient,_xlfn.XLOOKUP(_xlpm.food,_xlpm.names,FoodLibrary[Protein / 100g],0),IF(OR(_xlpm.food="",_xlpm.g=""),0,IFERROR(_xlpm.g*_xlpm.nutrient/_xlpm.base,0)))} -> 1 | G20: {=_xlfn.LET(_xlpm.food,TRIM(DailyIntake[[#This Row],[Food Name]]),_xlpm.g,DailyIntake[[#This Row],[Grams]],_xlpm.names,FoodLibrary[Lookup Key],_xlpm.custom,_xlfn.XLOOKUP(_xlpm.food,_xlpm.names,FoodLibrary[Custom],""),_xlpm.base,IFERROR(IF(VALUE(_xlpm.custom)>0,VALUE(_xlpm.custom),100),100),_xlpm.nutrient,_xlfn.XLOOKUP(_xlpm.food,_xlpm.names,FoodLibrary[Fat / 100g],0),IF(OR(_xlpm.food="",_xlpm.g=""),0,IFERROR(_xlpm.g*_xlpm.nutrient/_xlpm.base,0)))} -> 0.2 | I20: {=_xlfn.LET(_xlpm.food,TRIM(DailyIntake[[#This Row],[Food Name]]),_xlpm.names,FoodLibrary[Lookup Key],_xlpm.custom,_xlfn.XLOOKUP(_xlpm.food,_xlpm.names,FoodLibrary[Custom],""),_xlpm.base,IFERROR(VALUE(_xlpm.custom),0),IF(_xlpm.food="","",IF(_xlpm.base>0,"Food Library custom","Food Library /100g")))} -> Food Library /100g
A21: Meal 1 | B21: Optimum Protein Powder | C21: 30 | D21: {=_xlfn.LET(_xlpm.food,TRIM(DailyIntake[[#This Row],[Food Name]]),_xlpm.g,DailyIntake[[#This Row],[Grams]],_xlpm.names,FoodLibrary[Lookup Key],_xlpm.custom,_xlfn.XLOOKUP(_xlpm.food,_xlpm.names,FoodLibrary[Custom],""),_xlpm.base,IFERROR(IF(VALUE(_xlpm.custom)>0,VALUE(_xlpm.custom),100),100),_xlpm.nutrient,_xlfn.XLOOKUP(_xlpm.food,_xlpm.names,FoodLibrary[Calories / 100g],0),IF(OR(_xlpm.food="",_xlpm.g=""),0,IFERROR(_xlpm.g*_xlpm.nutrient/_xlpm.base,0)))} -> 117.43421 | E21: {=_xlfn.LET(_xlpm.food,TRIM(DailyIntake[[#This Row],[Food Name]]),_xlpm.g,DailyIntake[[#This Row],[Grams]],_xlpm.names,FoodLibrary[Lookup Key],_xlpm.custom,_xlfn.XLOOKUP(_xlpm.food,_xlpm.names,FoodLibrary[Custom],""),_xlpm.base,IFERROR(IF(VALUE(_xlpm.custom)>0,VALUE(_xlpm.custom),100),100),_xlpm.nutrient,_xlfn.XLOOKUP(_xlpm.food,_xlpm.names,FoodLibrary[Carbs / 100g],0),IF(OR(_xlpm.food="",_xlpm.g=""),0,IFERROR(_xlpm.g*_xlpm.nutrient/_xlpm.base,0)))} -> 2.9605263 | F21: {=_xlfn.LET(_xlpm.food,TRIM(DailyIntake[[#This Row],[Food Name]]),_xlpm.g,DailyIntake[[#This Row],[Grams]],_xlpm.names,FoodLibrary[Lookup Key],_xlpm.custom,_xlfn.XLOOKUP(_xlpm.food,_xlpm.names,FoodLibrary[Custom],""),_xlpm.base,IFERROR(IF(VALUE(_xlpm.custom)>0,VALUE(_xlpm.custom),100),100),_xlpm.nutrient,_xlfn.XLOOKUP(_xlpm.food,_xlpm.names,FoodLibrary[Protein / 100g],0),IF(OR(_xlpm.food="",_xlpm.g=""),0,IFERROR(_xlpm.g*_xlpm.nutrient/_xlpm.base,0)))} -> 23.684211 | G21: {=_xlfn.LET(_xlpm.food,TRIM(DailyIntake[[#This Row],[Food Name]]),_xlpm.g,DailyIntake[[#This Row],[Grams]],_xlpm.names,FoodLibrary[Lookup Key],_xlpm.custom,_xlfn.XLOOKUP(_xlpm.food,_xlpm.names,FoodLibrary[Custom],""),_xlpm.base,IFERROR(IF(VALUE(_xlpm.custom)>0,VALUE(_xlpm.custom),100),100),_xlpm.nutrient,_xlfn.XLOOKUP(_xlpm.food,_xlpm.names,FoodLibrary[Fat / 100g],0),IF(OR(_xlpm.food="",_xlpm.g=""),0,IFERROR(_xlpm.g*_xlpm.nutrient/_xlpm.base,0)))} -> 0.98684211 | I21: {=_xlfn.LET(_xlpm.food,TRIM(DailyIntake[[#This Row],[Food Name]]),_xlpm.names,FoodLibrary[Lookup Key],_xlpm.custom,_xlfn.XLOOKUP(_xlpm.food,_xlpm.names,FoodLibrary[Custom],""),_xlpm.base,IFERROR(VALUE(_xlpm.custom),0),IF(_xlpm.food="","",IF(_xlpm.base>0,"Food Library custom","Food Library /100g")))} -> Food Library /100g
A22: Meal 1 | B22: Creatine Blueberry | C22: 5 | D22: {=_xlfn.LET(_xlpm.food,TRIM(DailyIntake[[#This Row],[Food Name]]),_xlpm.g,DailyIntake[[#This Row],[Grams]],_xlpm.names,FoodLibrary[Lookup Key],_xlpm.custom,_xlfn.XLOOKUP(_xlpm.food,_xlpm.names,FoodLibrary[Custom],""),_xlpm.base,IFERROR(IF(VALUE(_xlpm.custom)>0,VALUE(_xlpm.custom),100),100),_xlpm.nutrient,_xlfn.XLOOKUP(_xlpm.food,_xlpm.names,FoodLibrary[Calories / 100g],0),IF(OR(_xlpm.food="",_xlpm.g=""),0,IFERROR(_xlpm.g*_xlpm.nutrient/_xlpm.base,0)))} -> 4.1666667 | E22: {=_xlfn.LET(_xlpm.food,TRIM(DailyIntake[[#This Row],[Food Name]]),_xlpm.g,DailyIntake[[#This Row],[Grams]],_xlpm.names,FoodLibrary[Lookup Key],_xlpm.custom,_xlfn.XLOOKUP(_xlpm.food,_xlpm.names,FoodLibrary[Custom],""),_xlpm.base,IFERROR(IF(VALUE(_xlpm.custom)>0,VALUE(_xlpm.custom),100),100),_xlpm.nutrient,_xlfn.XLOOKUP(_xlpm.food,_xlpm.names,FoodLibrary[Carbs / 100g],0),IF(OR(_xlpm.food="",_xlpm.g=""),0,IFERROR(_xlpm.g*_xlpm.nutrient/_xlpm.base,0)))} -> 0.83333333 | F22: {=_xlfn.LET(_xlpm.food,TRIM(DailyIntake[[#This Row],[Food Name]]),_xlpm.g,DailyIntake[[#This Row],[Grams]],_xlpm.names,FoodLibrary[Lookup Key],_xlpm.custom,_xlfn.XLOOKUP(_xlpm.food,_xlpm.names,FoodLibrary[Custom],""),_xlpm.base,IFERROR(IF(VALUE(_xlpm.custom)>0,VALUE(_xlpm.custom),100),100),_xlpm.nutrient,_xlfn.XLOOKUP(_xlpm.food,_xlpm.names,FoodLibrary[Protein / 100g],0),IF(OR(_xlpm.food="",_xlpm.g=""),0,IFERROR(_xlpm.g*_xlpm.nutrient/_xlpm.base,0)))} -> 0 | G22: {=_xlfn.LET(_xlpm.food,TRIM(DailyIntake[[#This Row],[Food Name]]),_xlpm.g,DailyIntake[[#This Row],[Grams]],_xlpm.names,FoodLibrary[Lookup Key],_xlpm.custom,_xlfn.XLOOKUP(_xlpm.food,_xlpm.names,FoodLibrary[Custom],""),_xlpm.base,IFERROR(IF(VALUE(_xlpm.custom)>0,VALUE(_xlpm.custom),100),100),_xlpm.nutrient,_xlfn.XLOOKUP(_xlpm.food,_xlpm.names,FoodLibrary[Fat / 100g],0),IF(OR(_xlpm.food="",_xlpm.g=""),0,IFERROR(_xlpm.g*_xlpm.nutrient/_xlpm.base,0)))} -> 0 | I22: {=_xlfn.LET(_xlpm.food,TRIM(DailyIntake[[#This Row],[Food Name]]),_xlpm.names,FoodLibrary[Lookup Key],_xlpm.custom,_xlfn.XLOOKUP(_xlpm.food,_xlpm.names,FoodLibrary[Custom],""),_xlpm.base,IFERROR(VALUE(_xlpm.custom),0),IF(_xlpm.food="","",IF(_xlpm.base>0,"Food Library custom","Food Library /100g")))} -> Food Library custom
A23: Meal 1 | B23: Optimum Amino/Electrolyde | C23: 3 | D23: {=_xlfn.LET(_xlpm.food,TRIM(DailyIntake[[#This Row],[Food Name]]),_xlpm.g,DailyIntake[[#This Row],[Grams]],_xlpm.names,FoodLibrary[Lookup Key],_xlpm.custom,_xlfn.XLOOKUP(_xlpm.food,_xlpm.names,FoodLibrary[Custom],""),_xlpm.base,IFERROR(IF(VALUE(_xlpm.custom)>0,VALUE(_xlpm.custom),100),100),_xlpm.nutrient,_xlfn.XLOOKUP(_xlpm.food,_xlpm.names,FoodLibrary[Calories / 100g],0),IF(OR(_xlpm.food="",_xlpm.g=""),0,IFERROR(_xlpm.g*_xlpm.nutrient/_xlpm.base,0)))} -> 1.3333333 | E23: {=_xlfn.LET(_xlpm.food,TRIM(DailyIntake[[#This Row],[Food Name]]),_xlpm.g,DailyIntake[[#This Row],[Grams]],_xlpm.names,FoodLibrary[Lookup Key],_xlpm.custom,_xlfn.XLOOKUP(_xlpm.food,_xlpm.names,FoodLibrary[Custom],""),_xlpm.base,IFERROR(IF(VALUE(_xlpm.custom)>0,VALUE(_xlpm.custom),100),100),_xlpm.nutrient,_xlfn.XLOOKUP(_xlpm.food,_xlpm.names,FoodLibrary[Carbs / 100g],0),IF(OR(_xlpm.food="",_xlpm.g=""),0,IFERROR(_xlpm.g*_xlpm.nutrient/_xlpm.base,0)))} -> 0.33333333 | F23: {=_xlfn.LET(_xlpm.food,TRIM(DailyIntake[[#This Row],[Food Name]]),_xlpm.g,DailyIntake[[#This Row],[Grams]],_xlpm.names,FoodLibrary[Lookup Key],_xlpm.custom,_xlfn.XLOOKUP(_xlpm.food,_xlpm.names,FoodLibrary[Custom],""),_xlpm.base,IFERROR(IF(VALUE(_xlpm.custom)>0,VALUE(_xlpm.custom),100),100),_xlpm.nutrient,_xlfn.XLOOKUP(_xlpm.food,_xlpm.names,FoodLibrary[Protein / 100g],0),IF(OR(_xlpm.food="",_xlpm.g=""),0,IFERROR(_xlpm.g*_xlpm.nutrient/_xlpm.base,0)))} -> 0 | G23: {=_xlfn.LET(_xlpm.food,TRIM(DailyIntake[[#This Row],[Food Name]]),_xlpm.g,DailyIntake[[#This Row],[Grams]],_xlpm.names,FoodLibrary[Lookup Key],_xlpm.custom,_xlfn.XLOOKUP(_xlpm.food,_xlpm.names,FoodLibrary[Custom],""),_xlpm.base,IFERROR(IF(VALUE(_xlpm.custom)>0,VALUE(_xlpm.custom),100),100),_xlpm.nutrient,_xlfn.XLOOKUP(_xlpm.food,_xlpm.names,FoodLibrary[Fat / 100g],0),IF(OR(_xlpm.food="",_xlpm.g=""),0,IFERROR(_xlpm.g*_xlpm.nutrient/_xlpm.base,0)))} -> 0 | I23: {=_xlfn.LET(_xlpm.food,TRIM(DailyIntake[[#This Row],[Food Name]]),_xlpm.names,FoodLibrary[Lookup Key],_xlpm.custom,_xlfn.XLOOKUP(_xlpm.food,_xlpm.names,FoodLibrary[Custom],""),_xlpm.base,IFERROR(VALUE(_xlpm.custom),0),IF(_xlpm.food="","",IF(_xlpm.base>0,"Food Library custom","Food Library /100g")))} -> Food Library custom
A24: Meal 1 | B24: Coffee | C24: 1 | D24: {=_xlfn.LET(_xlpm.food,TRIM(DailyIntake[[#This Row],[Food Name]]),_xlpm.g,DailyIntake[[#This Row],[Grams]],_xlpm.names,FoodLibrary[Lookup Key],_xlpm.custom,_xlfn.XLOOKUP(_xlpm.food,_xlpm.names,FoodLibrary[Custom],""),_xlpm.base,IFERROR(IF(VALUE(_xlpm.custom)>0,VALUE(_xlpm.custom),100),100),_xlpm.nutrient,_xlfn.XLOOKUP(_xlpm.food,_xlpm.names,FoodLibrary[Calories / 100g],0),IF(OR(_xlpm.food="",_xlpm.g=""),0,IFERROR(_xlpm.g*_xlpm.nutrient/_xlpm.base,0)))} -> 40 | E24: {=_xlfn.LET(_xlpm.food,TRIM(DailyIntake[[#This Row],[Food Name]]),_xlpm.g,DailyIntake[[#This Row],[Grams]],_xlpm.names,FoodLibrary[Lookup Key],_xlpm.custom,_xlfn.XLOOKUP(_xlpm.food,_xlpm.names,FoodLibrary[Custom],""),_xlpm.base,IFERROR(IF(VALUE(_xlpm.custom)>0,VALUE(_xlpm.custom),100),100),_xlpm.nutrient,_xlfn.XLOOKUP(_xlpm.food,_xlpm.names,FoodLibrary[Carbs / 100g],0),IF(OR(_xlpm.food="",_xlpm.g=""),0,IFERROR(_xlpm.g*_xlpm.nutrient/_xlpm.base,0)))} -> 4.6 | F24: {=_xlfn.LET(_xlpm.food,TRIM(DailyIntake[[#This Row],[Food Name]]),_xlpm.g,DailyIntake[[#This Row],[Grams]],_xlpm.names,FoodLibrary[Lookup Key],_xlpm.custom,_xlfn.XLOOKUP(_xlpm.food,_xlpm.names,FoodLibrary[Custom],""),_xlpm.base,IFERROR(IF(VALUE(_xlpm.custom)>0,VALUE(_xlpm.custom),100),100),_xlpm.nutrient,_xlfn.XLOOKUP(_xlpm.food,_xlpm.names,FoodLibrary[Protein / 100g],0),IF(OR(_xlpm.food="",_xlpm.g=""),0,IFERROR(_xlpm.g*_xlpm.nutrient/_xlpm.base,0)))} -> 1.4 | G24: {=_xlfn.LET(_xlpm.food,TRIM(DailyIntake[[#This Row],[Food Name]]),_xlpm.g,DailyIntake[[#This Row],[Grams]],_xlpm.names,FoodLibrary[Lookup Key],_xlpm.custom,_xlfn.XLOOKUP(_xlpm.food,_xlpm.names,FoodLibrary[Custom],""),_xlpm.base,IFERROR(IF(VALUE(_xlpm.custom)>0,VALUE(_xlpm.custom),100),100),_xlpm.nutrient,_xlfn.XLOOKUP(_xlpm.food,_xlpm.names,FoodLibrary[Fat / 100g],0),IF(OR(_xlpm.food="",_xlpm.g=""),0,IFERROR(_xlpm.g*_xlpm.nutrient/_xlpm.base,0)))} -> 1.6 | I24: {=_xlfn.LET(_xlpm.food,TRIM(DailyIntake[[#This Row],[Food Name]]),_xlpm.names,FoodLibrary[Lookup Key],_xlpm.custom,_xlfn.XLOOKUP(_xlpm.food,_xlpm.names,FoodLibrary[Custom],""),_xlpm.base,IFERROR(VALUE(_xlpm.custom),0),IF(_xlpm.food="","",IF(_xlpm.base>0,"Food Library custom","Food Library /100g")))} -> Food Library custom
A25: Meal 1 | D25: {=_xlfn.LET(_xlpm.food,TRIM(DailyIntake[[#This Row],[Food Name]]),_xlpm.g,DailyIntake[[#This Row],[Grams]],_xlpm.names,FoodLibrary[Lookup Key],_xlpm.custom,_xlfn.XLOOKUP(_xlpm.food,_xlpm.names,FoodLibrary[Custom],""),_xlpm.base,IFERROR(IF(VALUE(_xlpm.custom)>0,VALUE(_xlpm.custom),100),100),_xlpm.nutrient,_xlfn.XLOOKUP(_xlpm.food,_xlpm.names,FoodLibrary[Calories / 100g],0),IF(OR(_xlpm.food="",_xlpm.g=""),0,IFERROR(_xlpm.g*_xlpm.nutrient/_xlpm.base,0)))} -> 0 | E25: {=_xlfn.LET(_xlpm.food,TRIM(DailyIntake[[#This Row],[Food Name]]),_xlpm.g,DailyIntake[[#This Row],[Grams]],_xlpm.names,FoodLibrary[Lookup Key],_xlpm.custom,_xlfn.XLOOKUP(_xlpm.food,_xlpm.names,FoodLibrary[Custom],""),_xlpm.base,IFERROR(IF(VALUE(_xlpm.custom)>0,VALUE(_xlpm.custom),100),100),_xlpm.nutrient,_xlfn.XLOOKUP(_xlpm.food,_xlpm.names,FoodLibrary[Carbs / 100g],0),IF(OR(_xlpm.food="",_xlpm.g=""),0,IFERROR(_xlpm.g*_xlpm.nutrient/_xlpm.base,0)))} -> 0 | F25: {=_xlfn.LET(_xlpm.food,TRIM(DailyIntake[[#This Row],[Food Name]]),_xlpm.g,DailyIntake[[#This Row],[Grams]],_xlpm.names,FoodLibrary[Lookup Key],_xlpm.custom,_xlfn.XLOOKUP(_xlpm.food,_xlpm.names,FoodLibrary[Custom],""),_xlpm.base,IFERROR(IF(VALUE(_xlpm.custom)>0,VALUE(_xlpm.custom),100),100),_xlpm.nutrient,_xlfn.XLOOKUP(_xlpm.food,_xlpm.names,FoodLibrary[Protein / 100g],0),IF(OR(_xlpm.food="",_xlpm.g=""),0,IFERROR(_xlpm.g*_xlpm.nutrient/_xlpm.base,0)))} -> 0 | G25: {=_xlfn.LET(_xlpm.food,TRIM(DailyIntake[[#This Row],[Food Name]]),_xlpm.g,DailyIntake[[#This Row],[Grams]],_xlpm.names,FoodLibrary[Lookup Key],_xlpm.custom,_xlfn.XLOOKUP(_xlpm.food,_xlpm.names,FoodLibrary[Custom],""),_xlpm.base,IFERROR(IF(VALUE(_xlpm.custom)>0,VALUE(_xlpm.custom),100),100),_xlpm.nutrient,_xlfn.XLOOKUP(_xlpm.food,_xlpm.names,FoodLibrary[Fat / 100g],0),IF(OR(_xlpm.food="",_xlpm.g=""),0,IFERROR(_xlpm.g*_xlpm.nutrient/_xlpm.base,0)))} -> 0 | I25: {=_xlfn.LET(_xlpm.food,TRIM(DailyIntake[[#This Row],[Food Name]]),_xlpm.names,FoodLibrary[Lookup Key],_xlpm.custom,_xlfn.XLOOKUP(_xlpm.food,_xlpm.names,FoodLibrary[Custom],""),_xlpm.base,IFERROR(VALUE(_xlpm.custom),0),IF(_xlpm.food="","",IF(_xlpm.base>0,"Food Library custom","Food Library /100g")))}
A26: Meal 1 | D26: {=_xlfn.LET(_xlpm.food,TRIM(DailyIntake[[#This Row],[Food Name]]),_xlpm.g,DailyIntake[[#This Row],[Grams]],_xlpm.names,FoodLibrary[Lookup Key],_xlpm.custom,_xlfn.XLOOKUP(_xlpm.food,_xlpm.names,FoodLibrary[Custom],""),_xlpm.base,IFERROR(IF(VALUE(_xlpm.custom)>0,VALUE(_xlpm.custom),100),100),_xlpm.nutrient,_xlfn.XLOOKUP(_xlpm.food,_xlpm.names,FoodLibrary[Calories / 100g],0),IF(OR(_xlpm.food="",_xlpm.g=""),0,IFERROR(_xlpm.g*_xlpm.nutrient/_xlpm.base,0)))} -> 0 | E26: {=_xlfn.LET(_xlpm.food,TRIM(DailyIntake[[#This Row],[Food Name]]),_xlpm.g,DailyIntake[[#This Row],[Grams]],_xlpm.names,FoodLibrary[Lookup Key],_xlpm.custom,_xlfn.XLOOKUP(_xlpm.food,_xlpm.names,FoodLibrary[Custom],""),_xlpm.base,IFERROR(IF(VALUE(_xlpm.custom)>0,VALUE(_xlpm.custom),100),100),_xlpm.nutrient,_xlfn.XLOOKUP(_xlpm.food,_xlpm.names,FoodLibrary[Carbs / 100g],0),IF(OR(_xlpm.food="",_xlpm.g=""),0,IFERROR(_xlpm.g*_xlpm.nutrient/_xlpm.base,0)))} -> 0 | F26: {=_xlfn.LET(_xlpm.food,TRIM(DailyIntake[[#This Row],[Food Name]]),_xlpm.g,DailyIntake[[#This Row],[Grams]],_xlpm.names,FoodLibrary[Lookup Key],_xlpm.custom,_xlfn.XLOOKUP(_xlpm.food,_xlpm.names,FoodLibrary[Custom],""),_xlpm.base,IFERROR(IF(VALUE(_xlpm.custom)>0,VALUE(_xlpm.custom),100),100),_xlpm.nutrient,_xlfn.XLOOKUP(_xlpm.food,_xlpm.names,FoodLibrary[Protein / 100g],0),IF(OR(_xlpm.food="",_xlpm.g=""),0,IFERROR(_xlpm.g*_xlpm.nutrient/_xlpm.base,0)))} -> 0 | G26: {=_xlfn.LET(_xlpm.food,TRIM(DailyIntake[[#This Row],[Food Name]]),_xlpm.g,DailyIntake[[#This Row],[Grams]],_xlpm.names,FoodLibrary[Lookup Key],_xlpm.custom,_xlfn.XLOOKUP(_xlpm.food,_xlpm.names,FoodLibrary[Custom],""),_xlpm.base,IFERROR(IF(VALUE(_xlpm.custom)>0,VALUE(_xlpm.custom),100),100),_xlpm.nutrient,_xlfn.XLOOKUP(_xlpm.food,_xlpm.names,FoodLibrary[Fat / 100g],0),IF(OR(_xlpm.food="",_xlpm.g=""),0,IFERROR(_xlpm.g*_xlpm.nutrient/_xlpm.base,0)))} -> 0 | I26: {=_xlfn.LET(_xlpm.food,TRIM(DailyIntake[[#This Row],[Food Name]]),_xlpm.names,FoodLibrary[Lookup Key],_xlpm.custom,_xlfn.XLOOKUP(_xlpm.food,_xlpm.names,FoodLibrary[Custom],""),_xlpm.base,IFERROR(VALUE(_xlpm.custom),0),IF(_xlpm.food="","",IF(_xlpm.base>0,"Food Library custom","Food Library /100g")))}
A27: Meal 1 | D27: {=_xlfn.LET(_xlpm.food,TRIM(DailyIntake[[#This Row],[Food Name]]),_xlpm.g,DailyIntake[[#This Row],[Grams]],_xlpm.names,FoodLibrary[Lookup Key],_xlpm.custom,_xlfn.XLOOKUP(_xlpm.food,_xlpm.names,FoodLibrary[Custom],""),_xlpm.base,IFERROR(IF(VALUE(_xlpm.custom)>0,VALUE(_xlpm.custom),100),100),_xlpm.nutrient,_xlfn.XLOOKUP(_xlpm.food,_xlpm.names,FoodLibrary[Calories / 100g],0),IF(OR(_xlpm.food="",_xlpm.g=""),0,IFERROR(_xlpm.g*_xlpm.nutrient/_xlpm.base,0)))} -> 0 | E27: {=_xlfn.LET(_xlpm.food,TRIM(DailyIntake[[#This Row],[Food Name]]),_xlpm.g,DailyIntake[[#This Row],[Grams]],_xlpm.names,FoodLibrary[Lookup Key],_xlpm.custom,_xlfn.XLOOKUP(_xlpm.food,_xlpm.names,FoodLibrary[Custom],""),_xlpm.base,IFERROR(IF(VALUE(_xlpm.custom)>0,VALUE(_xlpm.custom),100),100),_xlpm.nutrient,_xlfn.XLOOKUP(_xlpm.food,_xlpm.names,FoodLibrary[Carbs / 100g],0),IF(OR(_xlpm.food="",_xlpm.g=""),0,IFERROR(_xlpm.g*_xlpm.nutrient/_xlpm.base,0)))} -> 0 | F27: {=_xlfn.LET(_xlpm.food,TRIM(DailyIntake[[#This Row],[Food Name]]),_xlpm.g,DailyIntake[[#This Row],[Grams]],_xlpm.names,FoodLibrary[Lookup Key],_xlpm.custom,_xlfn.XLOOKUP(_xlpm.food,_xlpm.names,FoodLibrary[Custom],""),_xlpm.base,IFERROR(IF(VALUE(_xlpm.custom)>0,VALUE(_xlpm.custom),100),100),_xlpm.nutrient,_xlfn.XLOOKUP(_xlpm.food,_xlpm.names,FoodLibrary[Protein / 100g],0),IF(OR(_xlpm.food="",_xlpm.g=""),0,IFERROR(_xlpm.g*_xlpm.nutrient/_xlpm.base,0)))} -> 0 | G27: {=_xlfn.LET(_xlpm.food,TRIM(DailyIntake[[#This Row],[Food Name]]),_xlpm.g,DailyIntake[[#This Row],[Grams]],_xlpm.names,FoodLibrary[Lookup Key],_xlpm.custom,_xlfn.XLOOKUP(_xlpm.food,_xlpm.names,FoodLibrary[Custom],""),_xlpm.base,IFERROR(IF(VALUE(_xlpm.custom)>0,VALUE(_xlpm.custom),100),100),_xlpm.nutrient,_xlfn.XLOOKUP(_xlpm.food,_xlpm.names,FoodLibrary[Fat / 100g],0),IF(OR(_xlpm.food="",_xlpm.g=""),0,IFERROR(_xlpm.g*_xlpm.nutrient/_xlpm.base,0)))} -> 0 | I27: {=_xlfn.LET(_xlpm.food,TRIM(DailyIntake[[#This Row],[Food Name]]),_xlpm.names,FoodLibrary[Lookup Key],_xlpm.custom,_xlfn.XLOOKUP(_xlpm.food,_xlpm.names,FoodLibrary[Custom],""),_xlpm.base,IFERROR(VALUE(_xlpm.custom),0),IF(_xlpm.food="","",IF(_xlpm.base>0,"Food Library custom","Food Library /100g")))}
A28: Meal 2 | B28: White Rice | C28: 90 | D28: {=_xlfn.LET(_xlpm.food,TRIM(DailyIntake[[#This Row],[Food Name]]),_xlpm.g,DailyIntake[[#This Row],[Grams]],_xlpm.names,FoodLibrary[Lookup Key],_xlpm.custom,_xlfn.XLOOKUP(_xlpm.food,_xlpm.names,FoodLibrary[Custom],""),_xlpm.base,IFERROR(IF(VALUE(_xlpm.custom)>0,VALUE(_xlpm.custom),100),100),_xlpm.nutrient,_xlfn.XLOOKUP(_xlpm.food,_xlpm.names,FoodLibrary[Calories / 100g],0),IF(OR(_xlpm.food="",_xlpm.g=""),0,IFERROR(_xlpm.g*_xlpm.nutrient/_xlpm.base,0)))} -> 324 | E28: {=_xlfn.LET(_xlpm.food,TRIM(DailyIntake[[#This Row],[Food Name]]),_xlpm.g,DailyIntake[[#This Row],[Grams]],_xlpm.names,FoodLibrary[Lookup Key],_xlpm.custom,_xlfn.XLOOKUP(_xlpm.food,_xlpm.names,FoodLibrary[Custom],""),_xlpm.base,IFERROR(IF(VALUE(_xlpm.custom)>0,VALUE(_xlpm.custom),100),100),_xlpm.nutrient,_xlfn.XLOOKUP(_xlpm.food,_xlpm.names,FoodLibrary[Carbs / 100g],0),IF(OR(_xlpm.food="",_xlpm.g=""),0,IFERROR(_xlpm.g*_xlpm.nutrient/_xlpm.base,0)))} -> 73.8 | F28: {=_xlfn.LET(_xlpm.food,TRIM(DailyIntake[[#This Row],[Food Name]]),_xlpm.g,DailyIntake[[#This Row],[Grams]],_xlpm.names,FoodLibrary[Lookup Key],_xlpm.custom,_xlfn.XLOOKUP(_xlpm.food,_xlpm.names,FoodLibrary[Custom],""),_xlpm.base,IFERROR(IF(VALUE(_xlpm.custom)>0,VALUE(_xlpm.custom),100),100),_xlpm.nutrient,_xlfn.XLOOKUP(_xlpm.food,_xlpm.names,FoodLibrary[Protein / 100g],0),IF(OR(_xlpm.food="",_xlpm.g=""),0,IFERROR(_xlpm.g*_xlpm.nutrient/_xlpm.base,0)))} -> 5.4 | G28: {=_xlfn.LET(_xlpm.food,TRIM(DailyIntake[[#This Row],[Food Name]]),_xlpm.g,DailyIntake[[#This Row],[Grams]],_xlpm.names,FoodLibrary[Lookup Key],_xlpm.custom,_xlfn.XLOOKUP(_xlpm.food,_xlpm.names,FoodLibrary[Custom],""),_xlpm.base,IFERROR(IF(VALUE(_xlpm.custom)>0,VALUE(_xlpm.custom),100),100),_xlpm.nutrient,_xlfn.XLOOKUP(_xlpm.food,_xlpm.names,FoodLibrary[Fat / 100g],0),IF(OR(_xlpm.food="",_xlpm.g=""),0,IFERROR(_xlpm.g*_xlpm.nutrient/_xlpm.base,0)))} -> 0 | I28: {=_xlfn.LET(_xlpm.food,TRIM(DailyIntake[[#This Row],[Food Name]]),_xlpm.names,FoodLibrary[Lookup Key],_xlpm.custom,_xlfn.XLOOKUP(_xlpm.food,_xlpm.names,FoodLibrary[Custom],""),_xlpm.base,IFERROR(VALUE(_xlpm.custom),0),IF(_xlpm.food="","",IF(_xlpm.base>0,"Food Library custom","Food Library /100g")))} -> Food Library /100g
A29: Meal 2 | B29: Chicken Breast | C29: 180 | D29: {=_xlfn.LET(_xlpm.food,TRIM(DailyIntake[[#This Row],[Food Name]]),_xlpm.g,DailyIntake[[#This Row],[Grams]],_xlpm.names,FoodLibrary[Lookup Key],_xlpm.custom,_xlfn.XLOOKUP(_xlpm.food,_xlpm.names,FoodLibrary[Custom],""),_xlpm.base,IFERROR(IF(VALUE(_xlpm.custom)>0,VALUE(_xlpm.custom),100),100),_xlpm.nutrient,_xlfn.XLOOKUP(_xlpm.food,_xlpm.names,FoodLibrary[Calories / 100g],0),IF(OR(_xlpm.food="",_xlpm.g=""),0,IFERROR(_xlpm.g*_xlpm.nutrient/_xlpm.base,0)))} -> 237.6 | E29: {=_xlfn.LET(_xlpm.food,TRIM(DailyIntake[[#This Row],[Food Name]]),_xlpm.g,DailyIntake[[#This Row],[Grams]],_xlpm.names,FoodLibrary[Lookup Key],_xlpm.custom,_xlfn.XLOOKUP(_xlpm.food,_xlpm.names,FoodLibrary[Custom],""),_xlpm.base,IFERROR(IF(VALUE(_xlpm.custom)>0,VALUE(_xlpm.custom),100),100),_xlpm.nutrient,_xlfn.XLOOKUP(_xlpm.food,_xlpm.names,FoodLibrary[Carbs / 100g],0),IF(OR(_xlpm.food="",_xlpm.g=""),0,IFERROR(_xlpm.g*_xlpm.nutrient/_xlpm.base,0)))} -> 0 | F29: {=_xlfn.LET(_xlpm.food,TRIM(DailyIntake[[#This Row],[Food Name]]),_xlpm.g,DailyIntake[[#This Row],[Grams]],_xlpm.names,FoodLibrary[Lookup Key],_xlpm.custom,_xlfn.XLOOKUP(_xlpm.food,_xlpm.names,FoodLibrary[Custom],""),_xlpm.base,IFERROR(IF(VALUE(_xlpm.custom)>0,VALUE(_xlpm.custom),100),100),_xlpm.nutrient,_xlfn.XLOOKUP(_xlpm.food,_xlpm.names,FoodLibrary[Protein / 100g],0),IF(OR(_xlpm.food="",_xlpm.g=""),0,IFERROR(_xlpm.g*_xlpm.nutrient/_xlpm.base,0)))} -> 32.94 | G29: {=_xlfn.LET(_xlpm.food,TRIM(DailyIntake[[#This Row],[Food Name]]),_xlpm.g,DailyIntake[[#This Row],[Grams]],_xlpm.names,FoodLibrary[Lookup Key],_xlpm.custom,_xlfn.XLOOKUP(_xlpm.food,_xlpm.names,FoodLibrary[Custom],""),_xlpm.base,IFERROR(IF(VALUE(_xlpm.custom)>0,VALUE(_xlpm.custom),100),100),_xlpm.nutrient,_xlfn.XLOOKUP(_xlpm.food,_xlpm.names,FoodLibrary[Fat / 100g],0),IF(OR(_xlpm.food="",_xlpm.g=""),0,IFERROR(_xlpm.g*_xlpm.nutrient/_xlpm.base,0)))} -> 11.7 | I29: {=_xlfn.LET(_xlpm.food,TRIM(DailyIntake[[#This Row],[Food Name]]),_xlpm.names,FoodLibrary[Lookup Key],_xlpm.custom,_xlfn.XLOOKUP(_xlpm.food,_xlpm.names,FoodLibrary[Custom],""),_xlpm.base,IFERROR(VALUE(_xlpm.custom),0),IF(_xlpm.food="","",IF(_xlpm.base>0,"Food Library custom","Food Library /100g")))} -> Food Library /100g
A30: Meal 2 | B30: Egg Yolk | C30: 17 | D30: {=_xlfn.LET(_xlpm.food,TRIM(DailyIntake[[#This Row],[Food Name]]),_xlpm.g,DailyIntake[[#This Row],[Grams]],_xlpm.names,FoodLibrary[Lookup Key],_xlpm.custom,_xlfn.XLOOKUP(_xlpm.food,_xlpm.names,FoodLibrary[Custom],""),_xlpm.base,IFERROR(IF(VALUE(_xlpm.custom)>0,VALUE(_xlpm.custom),100),100),_xlpm.nutrient,_xlfn.XLOOKUP(_xlpm.food,_xlpm.names,FoodLibrary[Calories / 100g],0),IF(OR(_xlpm.food="",_xlpm.g=""),0,IFERROR(_xlpm.g*_xlpm.nutrient/_xlpm.base,0)))} -> 45.9 | E30: {=_xlfn.LET(_xlpm.food,TRIM(DailyIntake[[#This Row],[Food Name]]),_xlpm.g,DailyIntake[[#This Row],[Grams]],_xlpm.names,FoodLibrary[Lookup Key],_xlpm.custom,_xlfn.XLOOKUP(_xlpm.food,_xlpm.names,FoodLibrary[Custom],""),_xlpm.base,IFERROR(IF(VALUE(_xlpm.custom)>0,VALUE(_xlpm.custom),100),100),_xlpm.nutrient,_xlfn.XLOOKUP(_xlpm.food,_xlpm.names,FoodLibrary[Carbs / 100g],0),IF(OR(_xlpm.food="",_xlpm.g=""),0,IFERROR(_xlpm.g*_xlpm.nutrient/_xlpm.base,0)))} -> 0.34 | F30: {=_xlfn.LET(_xlpm.food,TRIM(DailyIntake[[#This Row],[Food Name]]),_xlpm.g,DailyIntake[[#This Row],[Grams]],_xlpm.names,FoodLibrary[Lookup Key],_xlpm.custom,_xlfn.XLOOKUP(_xlpm.food,_xlpm.names,FoodLibrary[Custom],""),_xlpm.base,IFERROR(IF(VALUE(_xlpm.custom)>0,VALUE(_xlpm.custom),100),100),_xlpm.nutrient,_xlfn.XLOOKUP(_xlpm.food,_xlpm.names,FoodLibrary[Protein / 100g],0),IF(OR(_xlpm.food="",_xlpm.g=""),0,IFERROR(_xlpm.g*_xlpm.nutrient/_xlpm.base,0)))} -> 2.38 | G30: {=_xlfn.LET(_xlpm.food,TRIM(DailyIntake[[#This Row],[Food Name]]),_xlpm.g,DailyIntake[[#This Row],[Grams]],_xlpm.names,FoodLibrary[Lookup Key],_xlpm.custom,_xlfn.XLOOKUP(_xlpm.food,_xlpm.names,FoodLibrary[Custom],""),_xlpm.base,IFERROR(IF(VALUE(_xlpm.custom)>0,VALUE(_xlpm.custom),100),100),_xlpm.nutrient,_xlfn.XLOOKUP(_xlpm.food,_xlpm.names,FoodLibrary[Fat / 100g],0),IF(OR(_xlpm.food="",_xlpm.g=""),0,IFERROR(_xlpm.g*_xlpm.nutrient/_xlpm.base,0)))} -> 3.91 | I30: {=_xlfn.LET(_xlpm.food,TRIM(DailyIntake[[#This Row],[Food Name]]),_xlpm.names,FoodLibrary[Lookup Key],_xlpm.custom,_xlfn.XLOOKUP(_xlpm.food,_xlpm.names,FoodLibrary[Custom],""),_xlpm.base,IFERROR(VALUE(_xlpm.custom),0),IF(_xlpm.food="","",IF(_xlpm.base>0,"Food Library custom","Food Library /100g")))} -> Food Library /100g
A31: Meal 2 | B31: Egg White | C31: 124 | D31: {=_xlfn.LET(_xlpm.food,TRIM(DailyIntake[[#This Row],[Food Name]]),_xlpm.g,DailyIntake[[#This Row],[Grams]],_xlpm.names,FoodLibrary[Lookup Key],_xlpm.custom,_xlfn.XLOOKUP(_xlpm.food,_xlpm.names,FoodLibrary[Custom],""),_xlpm.base,IFERROR(IF(VALUE(_xlpm.custom)>0,VALUE(_xlpm.custom),100),100),_xlpm.nutrient,_xlfn.XLOOKUP(_xlpm.food,_xlpm.names,FoodLibrary[Calories / 100g],0),IF(OR(_xlpm.food="",_xlpm.g=""),0,IFERROR(_xlpm.g*_xlpm.nutrient/_xlpm.base,0)))} -> 59.52 | E31: {=_xlfn.LET(_xlpm.food,TRIM(DailyIntake[[#This Row],[Food Name]]),_xlpm.g,DailyIntake[[#This Row],[Grams]],_xlpm.names,FoodLibrary[Lookup Key],_xlpm.custom,_xlfn.XLOOKUP(_xlpm.food,_xlpm.names,FoodLibrary[Custom],""),_xlpm.base,IFERROR(IF(VALUE(_xlpm.custom)>0,VALUE(_xlpm.custom),100),100),_xlpm.nutrient,_xlfn.XLOOKUP(_xlpm.food,_xlpm.names,FoodLibrary[Carbs / 100g],0),IF(OR(_xlpm.food="",_xlpm.g=""),0,IFERROR(_xlpm.g*_xlpm.nutrient/_xlpm.base,0)))} -> 0 | F31: {=_xlfn.LET(_xlpm.food,TRIM(DailyIntake[[#This Row],[Food Name]]),_xlpm.g,DailyIntake[[#This Row],[Grams]],_xlpm.names,FoodLibrary[Lookup Key],_xlpm.custom,_xlfn.XLOOKUP(_xlpm.food,_xlpm.names,FoodLibrary[Custom],""),_xlpm.base,IFERROR(IF(VALUE(_xlpm.custom)>0,VALUE(_xlpm.custom),100),100),_xlpm.nutrient,_xlfn.XLOOKUP(_xlpm.food,_xlpm.names,FoodLibrary[Protein / 100g],0),IF(OR(_xlpm.food="",_xlpm.g=""),0,IFERROR(_xlpm.g*_xlpm.nutrient/_xlpm.base,0)))} -> 13.64 | G31: {=_xlfn.LET(_xlpm.food,TRIM(DailyIntake[[#This Row],[Food Name]]),_xlpm.g,DailyIntake[[#This Row],[Grams]],_xlpm.names,FoodLibrary[Lookup Key],_xlpm.custom,_xlfn.XLOOKUP(_xlpm.food,_xlpm.names,FoodLibrary[Custom],""),_xlpm.base,IFERROR(IF(VALUE(_xlpm.custom)>0,VALUE(_xlpm.custom),100),100),_xlpm.nutrient,_xlfn.XLOOKUP(_xlpm.food,_xlpm.names,FoodLibrary[Fat / 100g],0),IF(OR(_xlpm.food="",_xlpm.g=""),0,IFERROR(_xlpm.g*_xlpm.nutrient/_xlpm.base,0)))} -> 0 | I31: {=_xlfn.LET(_xlpm.food,TRIM(DailyIntake[[#This Row],[Food Name]]),_xlpm.names,FoodLibrary[Lookup Key],_xlpm.custom,_xlfn.XLOOKUP(_xlpm.food,_xlpm.names,FoodLibrary[Custom],""),_xlpm.base,IFERROR(VALUE(_xlpm.custom),0),IF(_xlpm.food="","",IF(_xlpm.base>0,"Food Library custom","Food Library /100g")))} -> Food Library /100g
A32: Meal 2 | D32: {=_xlfn.LET(_xlpm.food,TRIM(DailyIntake[[#This Row],[Food Name]]),_xlpm.g,DailyIntake[[#This Row],[Grams]],_xlpm.names,FoodLibrary[Lookup Key],_xlpm.custom,_xlfn.XLOOKUP(_xlpm.food,_xlpm.names,FoodLibrary[Custom],""),_xlpm.base,IFERROR(IF(VALUE(_xlpm.custom)>0,VALUE(_xlpm.custom),100),100),_xlpm.nutrient,_xlfn.XLOOKUP(_xlpm.food,_xlpm.names,FoodLibrary[Calories / 100g],0),IF(OR(_xlpm.food="",_xlpm.g=""),0,IFERROR(_xlpm.g*_xlpm.nutrient/_xlpm.base,0)))} -> 0 | E32: {=_xlfn.LET(_xlpm.food,TRIM(DailyIntake[[#This Row],[Food Name]]),_xlpm.g,DailyIntake[[#This Row],[Grams]],_xlpm.names,FoodLibrary[Lookup Key],_xlpm.custom,_xlfn.XLOOKUP(_xlpm.food,_xlpm.names,FoodLibrary[Custom],""),_xlpm.base,IFERROR(IF(VALUE(_xlpm.custom)>0,VALUE(_xlpm.custom),100),100),_xlpm.nutrient,_xlfn.XLOOKUP(_xlpm.food,_xlpm.names,FoodLibrary[Carbs / 100g],0),IF(OR(_xlpm.food="",_xlpm.g=""),0,IFERROR(_xlpm.g*_xlpm.nutrient/_xlpm.base,0)))} -> 0 | F32: {=_xlfn.LET(_xlpm.food,TRIM(DailyIntake[[#This Row],[Food Name]]),_xlpm.g,DailyIntake[[#This Row],[Grams]],_xlpm.names,FoodLibrary[Lookup Key],_xlpm.custom,_xlfn.XLOOKUP(_xlpm.food,_xlpm.names,FoodLibrary[Custom],""),_xlpm.base,IFERROR(IF(VALUE(_xlpm.custom)>0,VALUE(_xlpm.custom),100),100),_xlpm.nutrient,_xlfn.XLOOKUP(_xlpm.food,_xlpm.names,FoodLibrary[Protein / 100g],0),IF(OR(_xlpm.food="",_xlpm.g=""),0,IFERROR(_xlpm.g*_xlpm.nutrient/_xlpm.base,0)))} -> 0 | G32: {=_xlfn.LET(_xlpm.food,TRIM(DailyIntake[[#This Row],[Food Name]]),_xlpm.g,DailyIntake[[#This Row],[Grams]],_xlpm.names,FoodLibrary[Lookup Key],_xlpm.custom,_xlfn.XLOOKUP(_xlpm.food,_xlpm.names,FoodLibrary[Custom],""),_xlpm.base,IFERROR(IF(VALUE(_xlpm.custom)>0,VALUE(_xlpm.custom),100),100),_xlpm.nutrient,_xlfn.XLOOKUP(_xlpm.food,_xlpm.names,FoodLibrary[Fat / 100g],0),IF(OR(_xlpm.food="",_xlpm.g=""),0,IFERROR(_xlpm.g*_xlpm.nutrient/_xlpm.base,0)))} -> 0 | I32: {=_xlfn.LET(_xlpm.food,TRIM(DailyIntake[[#This Row],[Food Name]]),_xlpm.names,FoodLibrary[Lookup Key],_xlpm.custom,_xlfn.XLOOKUP(_xlpm.food,_xlpm.names,FoodLibrary[Custom],""),_xlpm.base,IFERROR(VALUE(_xlpm.custom),0),IF(_xlpm.food="","",IF(_xlpm.base>0,"Food Library custom","Food Library /100g")))}
A33: Meal 2 | D33: {=_xlfn.LET(_xlpm.food,TRIM(DailyIntake[[#This Row],[Food Name]]),_xlpm.g,DailyIntake[[#This Row],[Grams]],_xlpm.names,FoodLibrary[Lookup Key],_xlpm.custom,_xlfn.XLOOKUP(_xlpm.food,_xlpm.names,FoodLibrary[Custom],""),_xlpm.base,IFERROR(IF(VALUE(_xlpm.custom)>0,VALUE(_xlpm.custom),100),100),_xlpm.nutrient,_xlfn.XLOOKUP(_xlpm.food,_xlpm.names,FoodLibrary[Calories / 100g],0),IF(OR(_xlpm.food="",_xlpm.g=""),0,IFERROR(_xlpm.g*_xlpm.nutrient/_xlpm.base,0)))} -> 0 | E33: {=_xlfn.LET(_xlpm.food,TRIM(DailyIntake[[#This Row],[Food Name]]),_xlpm.g,DailyIntake[[#This Row],[Grams]],_xlpm.names,FoodLibrary[Lookup Key],_xlpm.custom,_xlfn.XLOOKUP(_xlpm.food,_xlpm.names,FoodLibrary[Custom],""),_xlpm.base,IFERROR(IF(VALUE(_xlpm.custom)>0,VALUE(_xlpm.custom),100),100),_xlpm.nutrient,_xlfn.XLOOKUP(_xlpm.food,_xlpm.names,FoodLibrary[Carbs / 100g],0),IF(OR(_xlpm.food="",_xlpm.g=""),0,IFERROR(_xlpm.g*_xlpm.nutrient/_xlpm.base,0)))} -> 0 | F33: {=_xlfn.LET(_xlpm.food,TRIM(DailyIntake[[#This Row],[Food Name]]),_xlpm.g,DailyIntake[[#This Row],[Grams]],_xlpm.names,FoodLibrary[Lookup Key],_xlpm.custom,_xlfn.XLOOKUP(_xlpm.food,_xlpm.names,FoodLibrary[Custom],""),_xlpm.base,IFERROR(IF(VALUE(_xlpm.custom)>0,VALUE(_xlpm.custom),100),100),_xlpm.nutrient,_xlfn.XLOOKUP(_xlpm.food,_xlpm.names,FoodLibrary[Protein / 100g],0),IF(OR(_xlpm.food="",_xlpm.g=""),0,IFERROR(_xlpm.g*_xlpm.nutrient/_xlpm.base,0)))} -> 0 | G33: {=_xlfn.LET(_xlpm.food,TRIM(DailyIntake[[#This Row],[Food Name]]),_xlpm.g,DailyIntake[[#This Row],[Grams]],_xlpm.names,FoodLibrary[Lookup Key],_xlpm.custom,_xlfn.XLOOKUP(_xlpm.food,_xlpm.names,FoodLibrary[Custom],""),_xlpm.base,IFERROR(IF(VALUE(_xlpm.custom)>0,VALUE(_xlpm.custom),100),100),_xlpm.nutrient,_xlfn.XLOOKUP(_xlpm.food,_xlpm.names,FoodLibrary[Fat / 100g],0),IF(OR(_xlpm.food="",_xlpm.g=""),0,IFERROR(_xlpm.g*_xlpm.nutrient/_xlpm.base,0)))} -> 0 | I33: {=_xlfn.LET(_xlpm.food,TRIM(DailyIntake[[#This Row],[Food Name]]),_xlpm.names,FoodLibrary[Lookup Key],_xlpm.custom,_xlfn.XLOOKUP(_xlpm.food,_xlpm.names,FoodLibrary[Custom],""),_xlpm.base,IFERROR(VALUE(_xlpm.custom),0),IF(_xlpm.food="","",IF(_xlpm.base>0,"Food Library custom","Food Library /100g")))}
A34: Meal 2 | D34: {=_xlfn.LET(_xlpm.food,TRIM(DailyIntake[[#This Row],[Food Name]]),_xlpm.g,DailyIntake[[#This Row],[Grams]],_xlpm.names,FoodLibrary[Lookup Key],_xlpm.custom,_xlfn.XLOOKUP(_xlpm.food,_xlpm.names,FoodLibrary[Custom],""),_xlpm.base,IFERROR(IF(VALUE(_xlpm.custom)>0,VALUE(_xlpm.custom),100),100),_xlpm.nutrient,_xlfn.XLOOKUP(_xlpm.food,_xlpm.names,FoodLibrary[Calories / 100g],0),IF(OR(_xlpm.food="",_xlpm.g=""),0,IFERROR(_xlpm.g*_xlpm.nutrient/_xlpm.base,0)))} -> 0 | E34: {=_xlfn.LET(_xlpm.food,TRIM(DailyIntake[[#This Row],[Food Name]]),_xlpm.g,DailyIntake[[#This Row],[Grams]],_xlpm.names,FoodLibrary[Lookup Key],_xlpm.custom,_xlfn.XLOOKUP(_xlpm.food,_xlpm.names,FoodLibrary[Custom],""),_xlpm.base,IFERROR(IF(VALUE(_xlpm.custom)>0,VALUE(_xlpm.custom),100),100),_xlpm.nutrient,_xlfn.XLOOKUP(_xlpm.food,_xlpm.names,FoodLibrary[Carbs / 100g],0),IF(OR(_xlpm.food="",_xlpm.g=""),0,IFERROR(_xlpm.g*_xlpm.nutrient/_xlpm.base,0)))} -> 0 | F34: {=_xlfn.LET(_xlpm.food,TRIM(DailyIntake[[#This Row],[Food Name]]),_xlpm.g,DailyIntake[[#This Row],[Grams]],_xlpm.names,FoodLibrary[Lookup Key],_xlpm.custom,_xlfn.XLOOKUP(_xlpm.food,_xlpm.names,FoodLibrary[Custom],""),_xlpm.base,IFERROR(IF(VALUE(_xlpm.custom)>0,VALUE(_xlpm.custom),100),100),_xlpm.nutrient,_xlfn.XLOOKUP(_xlpm.food,_xlpm.names,FoodLibrary[Protein / 100g],0),IF(OR(_xlpm.food="",_xlpm.g=""),0,IFERROR(_xlpm.g*_xlpm.nutrient/_xlpm.base,0)))} -> 0 | G34: {=_xlfn.LET(_xlpm.food,TRIM(DailyIntake[[#This Row],[Food Name]]),_xlpm.g,DailyIntake[[#This Row],[Grams]],_xlpm.names,FoodLibrary[Lookup Key],_xlpm.custom,_xlfn.XLOOKUP(_xlpm.food,_xlpm.names,FoodLibrary[Custom],""),_xlpm.base,IFERROR(IF(VALUE(_xlpm.custom)>0,VALUE(_xlpm.custom),100),100),_xlpm.nutrient,_xlfn.XLOOKUP(_xlpm.food,_xlpm.names,FoodLibrary[Fat / 100g],0),IF(OR(_xlpm.food="",_xlpm.g=""),0,IFERROR(_xlpm.g*_xlpm.nutrient/_xlpm.base,0)))} -> 0 | I34: {=_xlfn.LET(_xlpm.food,TRIM(DailyIntake[[#This Row],[Food Name]]),_xlpm.names,FoodLibrary[Lookup Key],_xlpm.custom,_xlfn.XLOOKUP(_xlpm.food,_xlpm.names,FoodLibrary[Custom],""),_xlpm.base,IFERROR(VALUE(_xlpm.custom),0),IF(_xlpm.food="","",IF(_xlpm.base>0,"Food Library custom","Food Library /100g")))}
A35: Meal 2 | D35: {=_xlfn.LET(_xlpm.food,TRIM(DailyIntake[[#This Row],[Food Name]]),_xlpm.g,DailyIntake[[#This Row],[Grams]],_xlpm.names,FoodLibrary[Lookup Key],_xlpm.custom,_xlfn.XLOOKUP(_xlpm.food,_xlpm.names,FoodLibrary[Custom],""),_xlpm.base,IFERROR(IF(VALUE(_xlpm.custom)>0,VALUE(_xlpm.custom),100),100),_xlpm.nutrient,_xlfn.XLOOKUP(_xlpm.food,_xlpm.names,FoodLibrary[Calories / 100g],0),IF(OR(_xlpm.food="",_xlpm.g=""),0,IFERROR(_xlpm.g*_xlpm.nutrient/_xlpm.base,0)))} -> 0 | E35: {=_xlfn.LET(_xlpm.food,TRIM(DailyIntake[[#This Row],[Food Name]]),_xlpm.g,DailyIntake[[#This Row],[Grams]],_xlpm.names,FoodLibrary[Lookup Key],_xlpm.custom,_xlfn.XLOOKUP(_xlpm.food,_xlpm.names,FoodLibrary[Custom],""),_xlpm.base,IFERROR(IF(VALUE(_xlpm.custom)>0,VALUE(_xlpm.custom),100),100),_xlpm.nutrient,_xlfn.XLOOKUP(_xlpm.food,_xlpm.names,FoodLibrary[Carbs / 100g],0),IF(OR(_xlpm.food="",_xlpm.g=""),0,IFERROR(_xlpm.g*_xlpm.nutrient/_xlpm.base,0)))} -> 0 | F35: {=_xlfn.LET(_xlpm.food,TRIM(DailyIntake[[#This Row],[Food Name]]),_xlpm.g,DailyIntake[[#This Row],[Grams]],_xlpm.names,FoodLibrary[Lookup Key],_xlpm.custom,_xlfn.XLOOKUP(_xlpm.food,_xlpm.names,FoodLibrary[Custom],""),_xlpm.base,IFERROR(IF(VALUE(_xlpm.custom)>0,VALUE(_xlpm.custom),100),100),_xlpm.nutrient,_xlfn.XLOOKUP(_xlpm.food,_xlpm.names,FoodLibrary[Protein / 100g],0),IF(OR(_xlpm.food="",_xlpm.g=""),0,IFERROR(_xlpm.g*_xlpm.nutrient/_xlpm.base,0)))} -> 0 | G35: {=_xlfn.LET(_xlpm.food,TRIM(DailyIntake[[#This Row],[Food Name]]),_xlpm.g,DailyIntake[[#This Row],[Grams]],_xlpm.names,FoodLibrary[Lookup Key],_xlpm.custom,_xlfn.XLOOKUP(_xlpm.food,_xlpm.names,FoodLibrary[Custom],""),_xlpm.base,IFERROR(IF(VALUE(_xlpm.custom)>0,VALUE(_xlpm.custom),100),100),_xlpm.nutrient,_xlfn.XLOOKUP(_xlpm.food,_xlpm.names,FoodLibrary[Fat / 100g],0),IF(OR(_xlpm.food="",_xlpm.g=""),0,IFERROR(_xlpm.g*_xlpm.nutrient/_xlpm.base,0)))} -> 0 | I35: {=_xlfn.LET(_xlpm.food,TRIM(DailyIntake[[#This Row],[Food Name]]),_xlpm.names,FoodLibrary[Lookup Key],_xlpm.custom,_xlfn.XLOOKUP(_xlpm.food,_xlpm.names,FoodLibrary[Custom],""),_xlpm.base,IFERROR(VALUE(_xlpm.custom),0),IF(_xlpm.food="","",IF(_xlpm.base>0,"Food Library custom","Food Library /100g")))}
A36: Meal 2 | D36: {=_xlfn.LET(_xlpm.food,TRIM(DailyIntake[[#This Row],[Food Name]]),_xlpm.g,DailyIntake[[#This Row],[Grams]],_xlpm.names,FoodLibrary[Lookup Key],_xlpm.custom,_xlfn.XLOOKUP(_xlpm.food,_xlpm.names,FoodLibrary[Custom],""),_xlpm.base,IFERROR(IF(VALUE(_xlpm.custom)>0,VALUE(_xlpm.custom),100),100),_xlpm.nutrient,_xlfn.XLOOKUP(_xlpm.food,_xlpm.names,FoodLibrary[Calories / 100g],0),IF(OR(_xlpm.food="",_xlpm.g=""),0,IFERROR(_xlpm.g*_xlpm.nutrient/_xlpm.base,0)))} -> 0 | E36: {=_xlfn.LET(_xlpm.food,TRIM(DailyIntake[[#This Row],[Food Name]]),_xlpm.g,DailyIntake[[#This Row],[Grams]],_xlpm.names,FoodLibrary[Lookup Key],_xlpm.custom,_xlfn.XLOOKUP(_xlpm.food,_xlpm.names,FoodLibrary[Custom],""),_xlpm.base,IFERROR(IF(VALUE(_xlpm.custom)>0,VALUE(_xlpm.custom),100),100),_xlpm.nutrient,_xlfn.XLOOKUP(_xlpm.food,_xlpm.names,FoodLibrary[Carbs / 100g],0),IF(OR(_xlpm.food="",_xlpm.g=""),0,IFERROR(_xlpm.g*_xlpm.nutrient/_xlpm.base,0)))} -> 0 | F36: {=_xlfn.LET(_xlpm.food,TRIM(DailyIntake[[#This Row],[Food Name]]),_xlpm.g,DailyIntake[[#This Row],[Grams]],_xlpm.names,FoodLibrary[Lookup Key],_xlpm.custom,_xlfn.XLOOKUP(_xlpm.food,_xlpm.names,FoodLibrary[Custom],""),_xlpm.base,IFERROR(IF(VALUE(_xlpm.custom)>0,VALUE(_xlpm.custom),100),100),_xlpm.nutrient,_xlfn.XLOOKUP(_xlpm.food,_xlpm.names,FoodLibrary[Protein / 100g],0),IF(OR(_xlpm.food="",_xlpm.g=""),0,IFERROR(_xlpm.g*_xlpm.nutrient/_xlpm.base,0)))} -> 0 | G36: {=_xlfn.LET(_xlpm.food,TRIM(DailyIntake[[#This Row],[Food Name]]),_xlpm.g,DailyIntake[[#This Row],[Grams]],_xlpm.names,FoodLibrary[Lookup Key],_xlpm.custom,_xlfn.XLOOKUP(_xlpm.food,_xlpm.names,FoodLibrary[Custom],""),_xlpm.base,IFERROR(IF(VALUE(_xlpm.custom)>0,VALUE(_xlpm.custom),100),100),_xlpm.nutrient,_xlfn.XLOOKUP(_xlpm.food,_xlpm.names,FoodLibrary[Fat / 100g],0),IF(OR(_xlpm.food="",_xlpm.g=""),0,IFERROR(_xlpm.g*_xlpm.nutrient/_xlpm.base,0)))} -> 0 | I36: {=_xlfn.LET(_xlpm.food,TRIM(DailyIntake[[#This Row],[Food Name]]),_xlpm.names,FoodLibrary[Lookup Key],_xlpm.custom,_xlfn.XLOOKUP(_xlpm.food,_xlpm.names,FoodLibrary[Custom],""),_xlpm.base,IFERROR(VALUE(_xlpm.custom),0),IF(_xlpm.food="","",IF(_xlpm.base>0,"Food Library custom","Food Library /100g")))}
A37: Meal 2 | D37: {=_xlfn.LET(_xlpm.food,TRIM(DailyIntake[[#This Row],[Food Name]]),_xlpm.g,DailyIntake[[#This Row],[Grams]],_xlpm.names,FoodLibrary[Lookup Key],_xlpm.custom,_xlfn.XLOOKUP(_xlpm.food,_xlpm.names,FoodLibrary[Custom],""),_xlpm.base,IFERROR(IF(VALUE(_xlpm.custom)>0,VALUE(_xlpm.custom),100),100),_xlpm.nutrient,_xlfn.XLOOKUP(_xlpm.food,_xlpm.names,FoodLibrary[Calories / 100g],0),IF(OR(_xlpm.food="",_xlpm.g=""),0,IFERROR(_xlpm.g*_xlpm.nutrient/_xlpm.base,0)))} -> 0 | E37: {=_xlfn.LET(_xlpm.food,TRIM(DailyIntake[[#This Row],[Food Name]]),_xlpm.g,DailyIntake[[#This Row],[Grams]],_xlpm.names,FoodLibrary[Lookup Key],_xlpm.custom,_xlfn.XLOOKUP(_xlpm.food,_xlpm.names,FoodLibrary[Custom],""),_xlpm.base,IFERROR(IF(VALUE(_xlpm.custom)>0,VALUE(_xlpm.custom),100),100),_xlpm.nutrient,_xlfn.XLOOKUP(_xlpm.food,_xlpm.names,FoodLibrary[Carbs / 100g],0),IF(OR(_xlpm.food="",_xlpm.g=""),0,IFERROR(_xlpm.g*_xlpm.nutrient/_xlpm.base,0)))} -> 0 | F37: {=_xlfn.LET(_xlpm.food,TRIM(DailyIntake[[#This Row],[Food Name]]),_xlpm.g,DailyIntake[[#This Row],[Grams]],_xlpm.names,FoodLibrary[Lookup Key],_xlpm.custom,_xlfn.XLOOKUP(_xlpm.food,_xlpm.names,FoodLibrary[Custom],""),_xlpm.base,IFERROR(IF(VALUE(_xlpm.custom)>0,VALUE(_xlpm.custom),100),100),_xlpm.nutrient,_xlfn.XLOOKUP(_xlpm.food,_xlpm.names,FoodLibrary[Protein / 100g],0),IF(OR(_xlpm.food="",_xlpm.g=""),0,IFERROR(_xlpm.g*_xlpm.nutrient/_xlpm.base,0)))} -> 0 | G37: {=_xlfn.LET(_xlpm.food,TRIM(DailyIntake[[#This Row],[Food Name]]),_xlpm.g,DailyIntake[[#This Row],[Grams]],_xlpm.names,FoodLibrary[Lookup Key],_xlpm.custom,_xlfn.XLOOKUP(_xlpm.food,_xlpm.names,FoodLibrary[Custom],""),_xlpm.base,IFERROR(IF(VALUE(_xlpm.custom)>0,VALUE(_xlpm.custom),100),100),_xlpm.nutrient,_xlfn.XLOOKUP(_xlpm.food,_xlpm.names,FoodLibrary[Fat / 100g],0),IF(OR(_xlpm.food="",_xlpm.g=""),0,IFERROR(_xlpm.g*_xlpm.nutrient/_xlpm.base,0)))} -> 0 | I37: {=_xlfn.LET(_xlpm.food,TRIM(DailyIntake[[#This Row],[Food Name]]),_xlpm.names,FoodLibrary[Lookup Key],_xlpm.custom,_xlfn.XLOOKUP(_xlpm.food,_xlpm.names,FoodLibrary[Custom],""),_xlpm.base,IFERROR(VALUE(_xlpm.custom),0),IF(_xlpm.food="","",IF(_xlpm.base>0,"Food Library custom","Food Library /100g")))}
A38: Meal 3 | B38: Sweet Potatoe | C38: 208 | D38: {=_xlfn.LET(_xlpm.food,TRIM(DailyIntake[[#This Row],[Food Name]]),_xlpm.g,DailyIntake[[#This Row],[Grams]],_xlpm.names,FoodLibrary[Lookup Key],_xlpm.custom,_xlfn.XLOOKUP(_xlpm.food,_xlpm.names,FoodLibrary[Custom],""),_xlpm.base,IFERROR(IF(VALUE(_xlpm.custom)>0,VALUE(_xlpm.custom),100),100),_xlpm.nutrient,_xlfn.XLOOKUP(_xlpm.food,_xlpm.names,FoodLibrary[Calories / 100g],0),IF(OR(_xlpm.food="",_xlpm.g=""),0,IFERROR(_xlpm.g*_xlpm.nutrient/_xlpm.base,0)))} -> 264.16 | E38: {=_xlfn.LET(_xlpm.food,TRIM(DailyIntake[[#This Row],[Food Name]]),_xlpm.g,DailyIntake[[#This Row],[Grams]],_xlpm.names,FoodLibrary[Lookup Key],_xlpm.custom,_xlfn.XLOOKUP(_xlpm.food,_xlpm.names,FoodLibrary[Custom],""),_xlpm.base,IFERROR(IF(VALUE(_xlpm.custom)>0,VALUE(_xlpm.custom),100),100),_xlpm.nutrient,_xlfn.XLOOKUP(_xlpm.food,_xlpm.names,FoodLibrary[Carbs / 100g],0),IF(OR(_xlpm.food="",_xlpm.g=""),0,IFERROR(_xlpm.g*_xlpm.nutrient/_xlpm.base,0)))} -> 66.56 | F38: {=_xlfn.LET(_xlpm.food,TRIM(DailyIntake[[#This Row],[Food Name]]),_xlpm.g,DailyIntake[[#This Row],[Grams]],_xlpm.names,FoodLibrary[Lookup Key],_xlpm.custom,_xlfn.XLOOKUP(_xlpm.food,_xlpm.names,FoodLibrary[Custom],""),_xlpm.base,IFERROR(IF(VALUE(_xlpm.custom)>0,VALUE(_xlpm.custom),100),100),_xlpm.nutrient,_xlfn.XLOOKUP(_xlpm.food,_xlpm.names,FoodLibrary[Protein / 100g],0),IF(OR(_xlpm.food="",_xlpm.g=""),0,IFERROR(_xlpm.g*_xlpm.nutrient/_xlpm.base,0)))} -> 2.496 | G38: {=_xlfn.LET(_xlpm.food,TRIM(DailyIntake[[#This Row],[Food Name]]),_xlpm.g,DailyIntake[[#This Row],[Grams]],_xlpm.names,FoodLibrary[Lookup Key],_xlpm.custom,_xlfn.XLOOKUP(_xlpm.food,_xlpm.names,FoodLibrary[Custom],""),_xlpm.base,IFERROR(IF(VALUE(_xlpm.custom)>0,VALUE(_xlpm.custom),100),100),_xlpm.nutrient,_xlfn.XLOOKUP(_xlpm.food,_xlpm.names,FoodLibrary[Fat / 100g],0),IF(OR(_xlpm.food="",_xlpm.g=""),0,IFERROR(_xlpm.g*_xlpm.nutrient/_xlpm.base,0)))} -> 0.416 | I38: {=_xlfn.LET(_xlpm.food,TRIM(DailyIntake[[#This Row],[Food Name]]),_xlpm.names,FoodLibrary[Lookup Key],_xlpm.custom,_xlfn.XLOOKUP(_xlpm.food,_xlpm.names,FoodLibrary[Custom],""),_xlpm.base,IFERROR(VALUE(_xlpm.custom),0),IF(_xlpm.food="","",IF(_xlpm.base>0,"Food Library custom","Food Library /100g")))} -> Food Library /100g
A39: Meal 3 | B39: Egg White | C39: 228 | D39: {=_xlfn.LET(_xlpm.food,TRIM(DailyIntake[[#This Row],[Food Name]]),_xlpm.g,DailyIntake[[#This Row],[Grams]],_xlpm.names,FoodLibrary[Lookup Key],_xlpm.custom,_xlfn.XLOOKUP(_xlpm.food,_xlpm.names,FoodLibrary[Custom],""),_xlpm.base,IFERROR(IF(VALUE(_xlpm.custom)>0,VALUE(_xlpm.custom),100),100),_xlpm.nutrient,_xlfn.XLOOKUP(_xlpm.food,_xlpm.names,FoodLibrary[Calories / 100g],0),IF(OR(_xlpm.food="",_xlpm.g=""),0,IFERROR(_xlpm.g*_xlpm.nutrient/_xlpm.base,0)))} -> 109.44 | E39: {=_xlfn.LET(_xlpm.food,TRIM(DailyIntake[[#This Row],[Food Name]]),_xlpm.g,DailyIntake[[#This Row],[Grams]],_xlpm.names,FoodLibrary[Lookup Key],_xlpm.custom,_xlfn.XLOOKUP(_xlpm.food,_xlpm.names,FoodLibrary[Custom],""),_xlpm.base,IFERROR(IF(VALUE(_xlpm.custom)>0,VALUE(_xlpm.custom),100),100),_xlpm.nutrient,_xlfn.XLOOKUP(_xlpm.food,_xlpm.names,FoodLibrary[Carbs / 100g],0),IF(OR(_xlpm.food="",_xlpm.g=""),0,IFERROR(_xlpm.g*_xlpm.nutrient/_xlpm.base,0)))} -> 0 | F39: {=_xlfn.LET(_xlpm.food,TRIM(DailyIntake[[#This Row],[Food Name]]),_xlpm.g,DailyIntake[[#This Row],[Grams]],_xlpm.names,FoodLibrary[Lookup Key],_xlpm.custom,_xlfn.XLOOKUP(_xlpm.food,_xlpm.names,FoodLibrary[Custom],""),_xlpm.base,IFERROR(IF(VALUE(_xlpm.custom)>0,VALUE(_xlpm.custom),100),100),_xlpm.nutrient,_xlfn.XLOOKUP(_xlpm.food,_xlpm.names,FoodLibrary[Protein / 100g],0),IF(OR(_xlpm.food="",_xlpm.g=""),0,IFERROR(_xlpm.g*_xlpm.nutrient/_xlpm.base,0)))} -> 25.08 | G39: {=_xlfn.LET(_xlpm.food,TRIM(DailyIntake[[#This Row],[Food Name]]),_xlpm.g,DailyIntake[[#This Row],[Grams]],_xlpm.names,FoodLibrary[Lookup Key],_xlpm.custom,_xlfn.XLOOKUP(_xlpm.food,_xlpm.names,FoodLibrary[Custom],""),_xlpm.base,IFERROR(IF(VALUE(_xlpm.custom)>0,VALUE(_xlpm.custom),100),100),_xlpm.nutrient,_xlfn.XLOOKUP(_xlpm.food,_xlpm.names,FoodLibrary[Fat / 100g],0),IF(OR(_xlpm.food="",_xlpm.g=""),0,IFERROR(_xlpm.g*_xlpm.nutrient/_xlpm.base,0)))} -> 0 | I39: {=_xlfn.LET(_xlpm.food,TRIM(DailyIntake[[#This Row],[Food Name]]),_xlpm.names,FoodLibrary[Lookup Key],_xlpm.custom,_xlfn.XLOOKUP(_xlpm.food,_xlpm.names,FoodLibrary[Custom],""),_xlpm.base,IFERROR(VALUE(_xlpm.custom),0),IF(_xlpm.food="","",IF(_xlpm.base>0,"Food Library custom","Food Library /100g")))} -> Food Library /100g
A40: Meal 3 | B40: Egg Yolk | C40: 14 | D40: {=_xlfn.LET(_xlpm.food,TRIM(DailyIntake[[#This Row],[Food Name]]),_xlpm.g,DailyIntake[[#This Row],[Grams]],_xlpm.names,FoodLibrary[Lookup Key],_xlpm.custom,_xlfn.XLOOKUP(_xlpm.food,_xlpm.names,FoodLibrary[Custom],""),_xlpm.base,IFERROR(IF(VALUE(_xlpm.custom)>0,VALUE(_xlpm.custom),100),100),_xlpm.nutrient,_xlfn.XLOOKUP(_xlpm.food,_xlpm.names,FoodLibrary[Calories / 100g],0),IF(OR(_xlpm.food="",_xlpm.g=""),0,IFERROR(_xlpm.g*_xlpm.nutrient/_xlpm.base,0)))} -> 37.8 | E40: {=_xlfn.LET(_xlpm.food,TRIM(DailyIntake[[#This Row],[Food Name]]),_xlpm.g,DailyIntake[[#This Row],[Grams]],_xlpm.names,FoodLibrary[Lookup Key],_xlpm.custom,_xlfn.XLOOKUP(_xlpm.food,_xlpm.names,FoodLibrary[Custom],""),_xlpm.base,IFERROR(IF(VALUE(_xlpm.custom)>0,VALUE(_xlpm.custom),100),100),_xlpm.nutrient,_xlfn.XLOOKUP(_xlpm.food,_xlpm.names,FoodLibrary[Carbs / 100g],0),IF(OR(_xlpm.food="",_xlpm.g=""),0,IFERROR(_xlpm.g*_xlpm.nutrient/_xlpm.base,0)))} -> 0.28 | F40: {=_xlfn.LET(_xlpm.food,TRIM(DailyIntake[[#This Row],[Food Name]]),_xlpm.g,DailyIntake[[#This Row],[Grams]],_xlpm.names,FoodLibrary[Lookup Key],_xlpm.custom,_xlfn.XLOOKUP(_xlpm.food,_xlpm.names,FoodLibrary[Custom],""),_xlpm.base,IFERROR(IF(VALUE(_xlpm.custom)>0,VALUE(_xlpm.custom),100),100),_xlpm.nutrient,_xlfn.XLOOKUP(_xlpm.food,_xlpm.names,FoodLibrary[Protein / 100g],0),IF(OR(_xlpm.food="",_xlpm.g=""),0,IFERROR(_xlpm.g*_xlpm.nutrient/_xlpm.base,0)))} -> 1.96 | G40: {=_xlfn.LET(_xlpm.food,TRIM(DailyIntake[[#This Row],[Food Name]]),_xlpm.g,DailyIntake[[#This Row],[Grams]],_xlpm.names,FoodLibrary[Lookup Key],_xlpm.custom,_xlfn.XLOOKUP(_xlpm.food,_xlpm.names,FoodLibrary[Custom],""),_xlpm.base,IFERROR(IF(VALUE(_xlpm.custom)>0,VALUE(_xlpm.custom),100),100),_xlpm.nutrient,_xlfn.XLOOKUP(_xlpm.food,_xlpm.names,FoodLibrary[Fat / 100g],0),IF(OR(_xlpm.food="",_xlpm.g=""),0,IFERROR(_xlpm.g*_xlpm.nutrient/_xlpm.base,0)))} -> 3.22 | I40: {=_xlfn.LET(_xlpm.food,TRIM(DailyIntake[[#This Row],[Food Name]]),_xlpm.names,FoodLibrary[Lookup Key],_xlpm.custom,_xlfn.XLOOKUP(_xlpm.food,_xlpm.names,FoodLibrary[Custom],""),_xlpm.base,IFERROR(VALUE(_xlpm.custom),0),IF(_xlpm.food="","",IF(_xlpm.base>0,"Food Library custom","Food Library /100g")))} -> Food Library /100g
